Workbook
Name Slicer_Category: #N/A
Name Slicer_Color: #N/A
Name Slicer_Size: #N/A

Sheet sales_entry
A1: Date | B1: Product ID | C1: Quantity Sold | D1: Selling Price | E1: Total Amount
A2: 01-01-2026 | B2: P001 | C2: 2 | D2: =_xlfn.XLOOKUP(B2,product_data[Product ID],product_data[Selling Price],0) -> 899 | E2: =C2*D2 -> 1798
A3: 01-01-2026 | B3: P005 | C3: 1 | D3: =_xlfn.XLOOKUP(B3,product_data[Product ID],product_data[Selling Price],0) -> 699 | E3: =C3*D3 -> 699
A4: 02-01-2026 | B4: P010 | C4: 3 | D4: =_xlfn.XLOOKUP(B4,product_data[Product ID],product_data[Selling Price],0) -> 1199 | E4: =C4*D4 -> 3597
A5: 02-01-2026 | B5: P013 | C5: 2 | D5: =_xlfn.XLOOKUP(B5,product_data[Product ID],product_data[Selling Price],0) -> 399 | E5: =C5*D5 -> 798
A6: 03-01-2026 | B6: P002 | C6: 1 | D6: =_xlfn.XLOOKUP(B6,product_data[Product ID],product_data[Selling Price],0) -> 849 | E6: =C6*D6 -> 849
A7: 03-01-2026 | B7: P018 | C7: 2 | D7: =_xlfn.XLOOKUP(B7,product_data[Product ID],product_data[Selling Price],0) -> 949 | E7: =C7*D7 -> 1898
A8: 04-01-2026 | B8: P009 | C8: 1 | D8: =_xlfn.XLOOKUP(B8,product_data[Product ID],product_data[Selling Price],0) -> 1299 | E8: =C8*D8 -> 1299
A9: 04-01-2026 | B9: P024 | C9: 3 | D9: =_xlfn.XLOOKUP(B9,product_data[Product ID],product_data[Selling Price],0) -> 299 | E9: =C9*D9 -> 897
A10: 05-01-2026 | B10: P003 | C10: 2 | D10: =_xlfn.XLOOKUP(B10,product_data[Product ID],product_data[Selling Price],0) -> 799 | E10: =C10*D10 -> 1598
A11: 05-01-2026 | B11: P015 | C11: 1 | D11: =_xlfn.XLOOKUP(B11,product_data[Product ID],product_data[Selling Price],0) -> 349 | E11: =C11*D11 -> 349
A12: 06-01-2026 | B12: P006 | C12: 2 | D12: =_xlfn.XLOOKUP(B12,product_data[Product ID],product_data[Selling Price],0) -> 649 | E12: =C12*D12 -> 1298
A13: 06-01-2026 | B13: P021 | C13: 1 | D13: =_xlfn.XLOOKUP(B13,product_data[Product ID],product_data[Selling Price],0) -> 1299 | E13: =C13*D13 -> 1299
... A61: 30-01-2026 | B61: P030 | C61: 1 | D61: =_xlfn.XLOOKUP(B61,product_data[Product ID],product_data[Selling Price],0) -> 649 | E61: =C61*D61 -> 649

Sheet pivot
A3: Row Labels | B3: Sum of Total Amount | E3: Row Labels | F3: Sum of Total Amount | H3: Total Revenue
A4: 01-01-2026 | B4: 2497 | E4: Jeans | F4: 25830 | H4: 73709
A5: 02-01-2026 | B5: 4395 | E5: Kurti | F5: 21876
A6: 03-01-2026 | B6: 2747 | E6: Shirt | F6: 13232
A7: 04-01-2026 | B7: 2196 | E7: Kidswear | F7: 12771 | H7: Total Sold
A8: 05-01-2026 | B8: 1947 | E8: Grand Total | F8: 73709 | H8: 91
A9: 06-01-2026 | B9: 2597
A10: 07-01-2026 | B10: 1997
A11: 08-01-2026 | B11: 2697 | H11: Avg Amount per Transaction
A12: 09-01-2026 | B12: 2298 | H12: 1228.4833
A13: 10-01-2026 | B13: 1997
A14: 11-01-2026 | B14: 2797
A15: 12-01-2026 | B15: 1648
A16: 13-01-2026 | B16: 2297
A17: 14-01-2026 | B17: 3497
A18: 15-01-2026 | B18: 2446 | F18: Row Labels | G18: Sum of Total Amount
A19: 16-01-2026 | B19: 1547 | F19: Regular Jeans | G19: 7194
A20: 17-01-2026 | B20: 2597 | F20: Slim Fit Jeans | G20: 5196
A21: 18-01-2026 | B21: 1497 | F21: Floral Kurti | G21: 4495
A22: 19-01-2026 | B22: 3247 | F22: Stretch Jeans | G22: 4197
A23: 20-01-2026 | B23: 1848 | F23: Cotton Kurti | G23: 3995
A24: 21-01-2026 | B24: 2597 | F24: Grand Total | G24: 25077
A25: 22-01-2026 | B25: 1897
A26: 23-01-2026 | B26: 3347
A27: 24-01-2026 | B27: 2797
A28: 25-01-2026 | B28: 1998
A29: 26-01-2026 | B29: 2197
A30: 27-01-2026 | B30: 2697 | F30: Item | G30: Stock
A31: 28-01-2026 | B31: 2645 | F31: Party Kurti | G31: 9
A32: 29-01-2026 | B32: 1898 | F32: Designer Kurti | G32: 7
A33: 30-01-2026 | B33: 2847 | F33: Regular Jeans | G33: 4
A34: Grand Total | B34: 73709 | F34: Denim Shirt | G34: 3
F39: Row Labels | G39: Sum of Quantity Sold
F40: S | G40: 32
F41: M | G41: 27
F42: L | G42: 23
F43: XL | G43: 9
F48: Item | G48: Profit
F49: Ripped Jeans | G49: 749
F50: Stretch Jeans | G50: 679
...

Sheet product_data
A1: Product ID | B1: Category | C1: Item Name | D1: Size | E1: Color | F1: Cost Price | G1: Selling Price | H1: Profit | I1: Stock | J1: Low Stock Alert | K1: Updated Stock
A2: P001 | B2: Kurti | C2: Floral Kurti | D2: S | E2: Blue | F2: 450 | G2: 899 | H2: =product_data[[#This Row],[Selling Price]]-product_data[[#This Row],[Cost Price]] -> 449 | I2: 25 | J2: =IF(I2<=10,"LOW","OK") -> OK | K2: =product_data[[#This Row],[Stock]]-SUMIF(sales_data[Product ID],product_data[[#This Row],[Product ID]],sales_data[Quantity Sold]) -> 20
A3: P002 | B3: Kurti | C3: Printed Kurti | D3: M | E3: Red | F3: 420 | G3: 849 | H3: =product_data[[#This Row],[Selling Price]]-product_data[[#This Row],[Cost Price]] -> 429 | I3: 18 | J3: =IF(I3<=10,"LOW","OK") -> OK | K3: =product_data[[#This Row],[Stock]]-SUMIF(sales_data[Product ID],product_data[[#This Row],[Product ID]],sales_data[Quantity Sold]) -> 15
A4: P003 | B4: Kurti | C4: Cotton Kurti | D4: L | E4: Green | F4: 380 | G4: 799 | H4: =product_data[[#This Row],[Selling Price]]-product_data[[#This Row],[Cost Price]] -> 419 | I4: 30 | J4: =IF(I4<=10,"LOW","OK") -> OK | K4: =product_data[[#This Row],[Stock]]-SUMIF(sales_data[Product ID],product_data[[#This Row],[Product ID]],sales_data[Quantity Sold]) -> 25
A5: P004 | B5: Kurti | C5: Designer Kurti | D5: XL | E5: Black | F5: 520 | G5: 999 | H5: =product_data[[#This Row],[Selling Price]]-product_data[[#This Row],[Cost Price]] -> 479 | I5: 9 | J5: =IF(I5<=10,"LOW","OK") -> LOW | K5: =product_data[[#This Row],[Stock]]-SUMIF(sales_data[Product ID],product_data[[#This Row],[Product ID]],sales_data[Quantity Sold]) -> 7
A6: P005 | B6: Shirt | C6: Formal Shirt | D6: S | E6: White | F6: 350 | G6: 699 | H6: =product_data[[#This Row],[Selling Price]]-product_data[[#This Row],[Cost Price]] -> 349 | I6: 40 | J6: =IF(I6<=10,"LOW","OK") -> OK | K6: =product_data[[#This Row],[Stock]]-SUMIF(sales_data[Product ID],product_data[[#This Row],[Product ID]],sales_data[Quantity Sold]) -> 37
A7: P006 | B7: Shirt | C7: Casual Shirt | D7: M | E7: Blue | F7: 300 | G7: 649 | H7: =product_data[[#This Row],[Selling Price]]-product_data[[#This Row],[Cost Price]] -> 349 | I7: 35 | J7: =IF(I7<=10,"LOW","OK") -> OK | K7: =product_data[[#This Row],[Stock]]-SUMIF(sales_data[Product ID],product_data[[#This Row],[Product ID]],sales_data[Quantity Sold]) -> 31
A8: P007 | B8: Shirt | C8: Checked Shirt | D8: L | E8: Red | F8: 320 | G8: 699 | H8: =product_data[[#This Row],[Selling Price]]-product_data[[#This Row],[Cost Price]] -> 379 | I8: 28 | J8: =IF(I8<=10,"LOW","OK") -> OK | K8: =product_data[[#This Row],[Stock]]-SUMIF(sales_data[Product ID],product_data[[#This Row],[Product ID]],sales_data[Quantity Sold]) -> 25
A9: P008 | B9: Shirt | C9: Linen Shirt | D9: XL | E9: Grey | F9: 400 | G9: 799 | H9: =product_data[[#This Row],[Selling Price]]-product_data[[#This Row],[Cost Price]] -> 399 | I9: 15 | J9: =IF(I9<=10,"LOW","OK") -> OK | K9: =product_data[[#This Row],[Stock]]-SUMIF(sales_data[Product ID],product_data[[#This Row],[Product ID]],sales_data[Quantity Sold]) -> 14
A10: P009 | B10: Jeans | C10: Slim Fit Jeans | D10: S | E10: Blue | F10: 700 | G10: 1299 | H10: =product_data[[#This Row],[Selling Price]]-product_data[[#This Row],[Cost Price]] -> 599 | I10: 22 | J10: =IF(I10<=10,"LOW","OK") -> OK | K10: =product_data[[#This Row],[Stock]]-SUMIF(sales_data[Product ID],product_data[[#This Row],[Product ID]],sales_data[Quantity Sold]) -> 18
A11: P010 | B11: Jeans | C11: Regular Jeans | D11: M | E11: Black | F11: 650 | G11: 1199 | H11: =product_data[[#This Row],[Selling Price]]-product_data[[#This Row],[Cost Price]] -> 549 | I11: 10 | J11: =IF(I11<=10,"LOW","OK") -> LOW | K11: =product_data[[#This Row],[Stock]]-SUMIF(sales_data[Product ID],product_data[[#This Row],[Product ID]],sales_data[Quantity Sold]) -> 4
A12: P011 | B12: Jeans | C12: Stretch Jeans | D12: L | E12: Grey | F12: 720 | G12: 1399 | H12: =product_data[[#This Row],[Selling Price]]-product_data[[#This Row],[Cost Price]] -> 679 | I12: 14 | J12: =IF(I12<=10,"LOW","OK") -> OK | K12: =product_data[[#This Row],[Stock]]-SUMIF(sales_data[Product ID],product_data[[#This Row],[Product ID]],sales_data[Quantity Sold]) -> 11
A13: P012 | B13: Jeans | C13: Ripped Jeans | D13: XL | E13: Blue | F13: 750 | G13: 1499 | H13: =product_data[[#This Row],[Selling Price]]-product_data[[#This Row],[Cost Price]] -> 749 | I13: 11 | J13: =IF(I13<=10,"LOW","OK") -> OK | K13: =product_data[[#This Row],[Stock]]-SUMIF(sales_data[Product ID],product_data[[#This Row],[Product ID]],sales_data[Quantity Sold]) -> 10
... A31: P030 | B31: Shirt | C31: Summer Shirt | D31: M | E31: Yellow | F31: 310 | G31: 649 | H31: =product_data[[#This Row],[Selling Price]]-product_data[[#This Row],[Cost Price]] -> 339 | I31: 27 | J31: =IF(I31<=10,"LOW","OK") -> OK | K31: =product_data[[#This Row],[Stock]]-SUMIF(sales_data[Product ID],product_data[[#This Row],[Product ID]],sales_data[Quantity Sold]) -> 24

Sheet Report
A1: Clothing Retail Sales & Inventory Management System
G4: Item with Low Stocks
G5: =pivot!F30 -> Item | H5: =pivot!G30 -> Stock
G6: =pivot!F31 -> Party Kurti | H6: =pivot!G31 -> 9
G7: =pivot!F32 -> Designer Kurti | H7: =pivot!G32 -> 7
D8: =pivot!H3 -> Total Revenue | E8: =pivot!H7 -> Total Sold | G8: =pivot!F33 -> Regular Jeans | H8: =pivot!G33 -> 4
D9: =pivot!H4 -> 73709 | E9: =pivot!H8 -> 91 | G9: =pivot!F34 -> Denim Shirt | H9: =pivot!G34 -> 3
